Workbook

Sheet DATA ENTRY
A1: Site | B1: Date_Julian | C1: Date | D1: VWR_veg | E1: Adj AWC_soil | F1: DTW_RP | G1: DTW_BGS | H1: On/Off
A2: BC1 | B2: =(C2-DATE(YEAR(C2),1,0))/365+YEAR(C2) -> 2025.4849 | C2: 45834 | D2: =ROUND(VLOOKUP(A2,'GB VWR July 1_2025'!A$4:C$33,2,FALSE),1) -> 22.3 | E2: 76.9 | F2: 2.425 | G2: =F2-VLOOKUP(A2,'test well RPs'!A:C,3,FALSE) -> 2.355 | H2: NA | J2: To update this master table - go to a link below & cut/paste the data from each monthly sheet (e.g., "Jan 2022 awc_dtw"):
A3: BC1 | B3: =(C3-DATE(YEAR(C3),1,0))/365+YEAR(C3) -> 2025.7315 | C3: 45924 | D3: =ROUND(VLOOKUP(A3,'GB VWR July 1_2025'!A$4:C$33,2,FALSE),1) -> 22.3 | E3: 67.8 | F3: 2.726 | G3: =F3-VLOOKUP(A3,'test well RPs'!A:C,3,FALSE) -> 2.656 | H3: NA | J3: S:\Shared_Files\Soil Water Monthly Data Entry\Files_monthly OR S:\staffdata\Tim\Soil Moisture_On_Off\AWC_DTW_monthly.
A4: BC1 | B4: =(C4-DATE(YEAR(C4),1,0))/365+YEAR(C4) -> 2025.8849 | C4: 45980 | D4: =ROUND(VLOOKUP(A4,'GB VWR July 1_2025'!A$4:C$33,2,FALSE),1) -> 22.3 | E4: 72.9 | F4: 2.774 | G4: =F4-VLOOKUP(A4,'test well RPs'!A:C,3,FALSE) -> 2.704 | H4: NA | J4: Sort on Site & remove TA1, TAC & TS6. Check each Hydrograph for any WLs flagged as erroneous (sometimes found months
A5: BC1 | B5: =(C5-DATE(YEAR(C5),1,0))/365+YEAR(C5) -> 2026.0575 | C5: 46043 | D5: =ROUND(VLOOKUP(A5,'GB VWR July 1_2025'!A$4:C$33,2,FALSE),1) -> 22.3 | E5: 81.7 | F5: 2.598 | G5: =F5-VLOOKUP(A5,'test well RPs'!A:C,3,FALSE) -> 2.528 | H5: NA | J5: later) and check min/max date range before copy/paste WL data to "dtw" tab. Then do some more sorting to get rid of NA/NR
A6: BC1 | B6: =(C6-DATE(YEAR(C6),1,0))/365+YEAR(C6) -> 2026.2274 | C6: 46105 | D6: =ROUND(VLOOKUP(A6,'GB VWR July 1_2025'!A$4:C$33,2,FALSE),1) -> 22.3 | E6: 82.5 | F6: 2.415 | G6: =F6-VLOOKUP(A6,'test well RPs'!A:C,3,FALSE) -> 2.345 | H6: NA | J6: reads and round values to one decimal place (if needed) before copy/paste to "awc_vwr" tab. Finally, update "on.off" tab.
A7: BC1 | B7: =(C7-DATE(YEAR(C7),1,0))/365+YEAR(C7) -> 2026.3041 | C7: 46133 | D7: =ROUND(VLOOKUP(A7,'GB VWR July 1_2025'!A$4:C$33,2,FALSE),1) -> 22.3 | E7: 78.5 | F7: 2.391 | G7: =F7-VLOOKUP(A7,'test well RPs'!A:C,3,FALSE) -> 2.321 | H7: NA
A8: BC2 | B8: =(C8-DATE(YEAR(C8),1,0))/365+YEAR(C8) -> 2025.4849 | C8: 45834 | D8: =ROUND(VLOOKUP(A8,'GB VWR July 1_2025'!A$4:C$33,2,FALSE),1) -> 19.1 | E8: 38 | F8: 4.069 | G8: =F8-VLOOKUP(A8,'test well RPs'!A:C,3,FALSE) -> 3.869 | H8: NA | J8: VWR change between end of May and June for July 1 VWR which is for the second half of the growing season. July 1 On/Off asks, is there enough soil water for the rest of the summer?
A9: BC2 | B9: =(C9-DATE(YEAR(C9),1,0))/365+YEAR(C9) -> 2025.7315 | C9: 45924 | D9: =ROUND(VLOOKUP(A9,'GB VWR July 1_2025'!A$4:C$33,2,FALSE),1) -> 19.1 | E9: 34.7 | F9: 4.358 | G9: =F9-VLOOKUP(A9,'test well RPs'!A:C,3,FALSE) -> 4.158 | H9: NA | J9: VWR change between end of August and September for October 1 VWR which is for the full growing season. Oct 1 On/Off asks, is there enough soil water for next summer to maintain
A10: BC2 | B10: =(C10-DATE(YEAR(C10),1,0))/365+YEAR(C10) -> 2025.8849 | C10: 45980 | D10: =ROUND(VLOOKUP(A10,'GB VWR July 1_2025'!A$4:C$33,2,FALSE),1) -> 19.1 | E10: 37.8 | F10: 4.362 | G10: =F10-VLOOKUP(A10,'test well RPs'!A:C,3,FALSE) -> 4.162 | H10: NA | J10: cover we had the summer just concluded? This is what we enter in the "awc_vwr" tab for the full 12 months.
A11: BC2 | B11: =(C11-DATE(YEAR(C11),1,0))/365+YEAR(C11) -> 2026.0575 | C11: 46043 | D11: =ROUND(VLOOKUP(A11,'GB VWR July 1_2025'!A$4:C$33,2,FALSE),1) -> 19.1 | E11: 44.9 | F11: 4.19 | G11: =F11-VLOOKUP(A11,'test well RPs'!A:C,3,FALSE) -> 3.99 | H11: NA
A12: BC2 | B12: =(C12-DATE(YEAR(C12),1,0))/365+YEAR(C12) -> 2026.2274 | C12: 46105 | D12: =ROUND(VLOOKUP(A12,'GB VWR July 1_2025'!A$4:C$33,2,FALSE),1) -> 19.1 | E12: 44.8 | F12: 4.148 | G12: =F12-VLOOKUP(A12,'test well RPs'!A:C,3,FALSE) -> 3.948 | H12: NA
A13: BC2 | B13: =(C13-DATE(YEAR(C13),1,0))/365+YEAR(C13) -> 2026.3041 | C13: 46133 | D13: =ROUND(VLOOKUP(A13,'GB VWR July 1_2025'!A$4:C$33,2,FALSE),1) -> 19.1 | E13: 42.6 | F13: 4.17 | G13: =F13-VLOOKUP(A13,'test well RPs'!A:C,3,FALSE) -> 3.97 | H13: NA | J13: Things to Fix in future updates
A14: BC3 | B14: =(C14-DATE(YEAR(C14),1,0))/365+YEAR(C14) -> 2025.4849 | C14: 45834 | D14: =ROUND(VLOOKUP(A14,'GB VWR July 1_2025'!A$4:C$33,2,FALSE),1) -> 18 | E14: 42.5 | F14: 1.672 | G14: =F14-VLOOKUP(A14,'test well RPs'!A:C,3,FALSE) -> 1.602 | H14: NA | J14: There is a discrepancy in data entry where sometimes vwr is entered as turn-on value or the lower July 1 value for just the 1st half
A15: BC3 | B15: =(C15-DATE(YEAR(C15),1,0))/365+YEAR(C15) -> 2025.7315 | C15: 45924 | D15: =ROUND(VLOOKUP(A15,'GB VWR July 1_2025'!A$4:C$33,2,FALSE),1) -> 18 | E15: 37.7 | F15: 2.026 | G15: =F15-VLOOKUP(A15,'test well RPs'!A:C,3,FALSE) -> 1.956 | H15: NA | J15: of the growing season (e.g., both issues are common in 2019) instead of calculated GB VWR Oct value for the full 12 months.
A16: BC3 | B16: =(C16-DATE(YEAR(C16),1,0))/365+YEAR(C16) -> 2025.8849 | C16: 45980 | D16: =ROUND(VLOOKUP(A16,'GB VWR July 1_2025'!A$4:C$33,2,FALSE),1) -> 18 | E16: 42.8 | F16: 1.864 | G16: =F16-VLOOKUP(A16,'test well RPs'!A:C,3,FALSE) -> 1.794 | H16: NA
A17: BC3 | B17: =(C17-DATE(YEAR(C17),1,0))/365+YEAR(C17) -> 2026.0575 | C17: 46043 | D17: =ROUND(VLOOKUP(A17,'GB VWR July 1_2025'!A$4:C$33,2,FALSE),1) -> 18 | E17: 49.1 | F17: 1.378 | G17: =F17-VLOOKUP(A17,'test well RPs'!A:C,3,FALSE) -> 1.308 | H17: NA
A18: BC3 | B18: =(C18-DATE(YEAR(C18),1,0))/365+YEAR(C18) -> 2026.2274 | C18: 46105 | D18: =ROUND(VLOOKUP(A18,'GB VWR July 1_2025'!A$4:C$33,2,FALSE),1) -> 18 | E18: 50.1 | F18: 1.285 | G18: =F18-VLOOKUP(A18,'test well RPs'!A:C,3,FALSE) -> 1.215 | H18: NA
A19: BC3 | B19: =(C19-DATE(YEAR(C19),1,0))/365+YEAR(C19) -> 2026.3041 | C19: 46133 | D19: =ROUND(VLOOKUP(A19,'GB VWR July 1_2025'!A$4:C$33,2,FALSE),1) -> 18 | E19: 47.1 | F19: 1.348 | G19: =F19-VLOOKUP(A19,'test well RPs'!A:C,3,FALSE) -> 1.278 | H19: NA
A20: BG2 | B20: =(C20-DATE(YEAR(C20),1,0))/365+YEAR(C20) -> 2025.4658 | C20: 45827 | D20: =ROUND(VLOOKUP(A20,'GB VWR July 1_2025'!A$4:C$33,2,FALSE),1) -> 9.8 | E20: 42.8 | F20: 3.895 | G20: =F20-VLOOKUP(A20,'test well RPs'!A:C,3,FALSE) -> 3.545 | H20: ON
A21: BG2 | B21: =(C21-DATE(YEAR(C21),1,0))/365+YEAR(C21) -> 2025.5726 | C21: 45866 | D21: =ROUND(VLOOKUP(A21,'GB VWR July 1_2025'!A$4:C$33,2,FALSE),1) -> 9.8 | E21: 39 | F21: 3.953 | G21: =F21-VLOOKUP(A21,'test well RPs'!A:C,3,FALSE) -> 3.603 | H21: ON
A22: BG2 | B22: =(C22-DATE(YEAR(C22),1,0))/365+YEAR(C22) -> 2025.6384 | C22: 45890 | D22: =ROUND(VLOOKUP(A22,'GB VWR July 1_2025'!A$4:C$33,2,FALSE),1) -> 9.8 | E22: 36.8 | F22: 3.987 | G22: =F22-VLOOKUP(A22,'test well RPs'!A:C,3,FALSE) -> 3.637 | H22: ON
A23: BG2 | B23: =(C23-DATE(YEAR(C23),1,0))/365+YEAR(C23) -> 2025.726 | C23: 45922 | D23: =ROUND(VLOOKUP(A23,'GB VWR July 1_2025'!A$4:C$33,2,FALSE),1) -> 9.8 | E23: 37 | F23: 4.031 | G23: =F23-VLOOKUP(A23,'test well RPs'!A:C,3,FALSE) -> 3.681 | H23: ON
A24: BG2 | B24: =(C24-DATE(YEAR(C24),1,0))/365+YEAR(C24) -> 2025.8219 | C24: 45957 | D24: =ROUND(VLOOKUP(A24,'GB VWR July 1_2025'!A$4:C$33,2,FALSE),1) -> 9.8 | E24: 37 | F24: 4.056 | G24: =F24-VLOOKUP(A24,'test well RPs'!A:C,3,FALSE) -> 3.706 | H24: ON
A25: BG2 | B25: =(C25-DATE(YEAR(C25),1,0))/365+YEAR(C25) -> 2025.9041 | C25: 45987 | D25: =ROUND(VLOOKUP(A25,'GB VWR July 1_2025'!A$4:C$33,2,FALSE),1) -> 9.8 | E25: 41.2 | F25: 4.08 | G25: =F25-VLOOKUP(A25,'test well RPs'!A:C,3,FALSE) -> 3.73 | H25: ON
A26: BG2 | B26: =(C26-DATE(YEAR(C26),1,0))/365+YEAR(C26) -> 2025.9726 | C26: 46012 | D26: =ROUND(VLOOKUP(A26,'GB VWR July 1_2025'!A$4:C$33,2,FALSE),1) -> 9.8 | E26: 38.8 | F26: 4.032 | G26: =F26-VLOOKUP(A26,'test well RPs'!A:C,3,FALSE) -> 3.682 | H26: ON
A27: BG2 | B27: =(C27-DATE(YEAR(C27),1,0))/365+YEAR(C27) -> 2026.074 | C27: 46049 | D27: =ROUND(VLOOKUP(A27,'GB VWR July 1_2025'!A$4:C$33,2,FALSE),1) -> 9.8 | E27: 40.5 | F27: 4.043 | G27: =F27-VLOOKUP(A27,'test well RPs'!A:C,3,FALSE) -> 3.693 | H27: ON
... A96: IC2 | B96: =(C96-DATE(YEAR(C96),1,0))/365+YEAR(C96) -> 2026.2329 | C96: 46107 | D96: =ROUND(VLOOKUP(A96,'GB VWR July 1_2025'!A$4:C$33,2,FALSE),1) -> 2.8 | E96: 25.4 | F96: 2.356 | G96: =F96-VLOOKUP(A96,'test well RPs'!A:C,3,FALSE) -> 2.196 | H96: NA
A97: IC2 | B97: =(C97-DATE(YEAR(C97),1,0))/365+YEAR(C97) -> 2026.3233 | C97: 46140 | D97: =ROUND(VLOOKUP(A97,'GB VWR July 1_2025'!A$4:C$33,2,FALSE),1) -> 2.8 | E97: 24.9 | F97: 2.524 | H97: NA
A98: IO1 | B98: =(C98-DATE(YEAR(C98),1,0))/365+YEAR(C98) -> 2025.4767 | C98: 45831 | D98: =ROUND(VLOOKUP(A98,'GB VWR July 1_2025'!A$4:C$33,2,FALSE),1) -> 31.8 | E98: 30.7 | F98: 3.304 | G98: =F98-VLOOKUP(A98,'test well RPs'!A:C,3,FALSE) -> 3.164 | H98: ON
A99: IO1 | B99: =(C99-DATE(YEAR(C99),1,0))/365+YEAR(C99) -> 2025.5616 | C99: 45862 | D99: =ROUND(VLOOKUP(A99,'GB VWR July 1_2025'!A$4:C$33,2,FALSE),1) -> 31.8 | E99: 27.9 | F99: 3.536 | G99: =F99-VLOOKUP(A99,'test well RPs'!A:C,3,FALSE) -> 3.396 | H99: ON
A100: IO1 | B100: =(C100-DATE(YEAR(C100),1,0))/365+YEAR(C100) -> 2025.6521 | C100: 45895 | D100: =ROUND(VLOOKUP(A100,'GB VWR July 1_2025'!A$4:C$33,2,FALSE),1) -> 31.8 | E100: 25.7 | F100: 3.675 | G100: =F100-VLOOKUP(A100,'test well RPs'!A:C,3,FALSE) -> 3.535 | H100: ON
A101: IO1 | B101: =(C101-DATE(YEAR(C101),1,0))/365+YEAR(C101) -> 2025.7288 | C101: 45923 | D101: =ROUND(VLOOKUP(A101,'GB VWR July 1_2025'!A$4:C$33,2,FALSE),1) -> 31.8 | E101: 24.4 | F101: 3.707 | G101: =F101-VLOOKUP(A101,'test well RPs'!A:C,3,FALSE) -> 3.567 | H101: OFF (31.8)
A102: IO1 | B102: =(C102-DATE(YEAR(C102),1,0))/365+YEAR(C102) -> 2025.8219 | C102: 45957 | D102: =ROUND(VLOOKUP(A102,'GB VWR July 1_2025'!A$4:C$33,2,FALSE),1) -> 31.8 | E102: 24.5 | F102: 3.589 | G102: =F102-VLOOKUP(A102,'test well RPs'!A:C,3,FALSE) -> 3.449 | H102: OFF (31.8)
A103: IO1 | B103: =(C103-DATE(YEAR(C103),1,0))/365+YEAR(C103) -> 2025.8986 | C103: 45985 | D103: =ROUND(VLOOKUP(A103,'GB VWR July 1_2025'!A$4:C$33,2,FALSE),1) -> 31.8 | E103: 25.1 | F103: 3.459 | G103: =F103-VLOOKUP(A103,'test well RPs'!A:C,3,FALSE) -> 3.319 | H103: OFF (31.8)
A104: IO1 | B104: =(C104-DATE(YEAR(C104),1,0))/365+YEAR(C104) -> 2025.9726 | C104: 46012 | D104: =ROUND(VLOOKUP(A104,'GB VWR July 1_2025'!A$4:C$33,2,FALSE),1) -> 31.8 | E104: 26.3 | F104: 3.338 | G104: =F104-VLOOKUP(A104,'test well RPs'!A:C,3,FALSE) -> 3.198 | H104: OFF (31.8)
A105: IO1 | B105: =(C105-DATE(YEAR(C105),1,0))/365+YEAR(C105) -> 2026.0712 | C105: 46048 | D105: =ROUND(VLOOKUP(A105,'GB VWR July 1_2025'!A$4:C$33,2,FALSE),1) -> 31.8 | E105: 31.2 | F105: 3.186 | G105: =F105-VLOOKUP(A105,'test well RPs'!A:C,3,FALSE) -> 3.046 | H105: OFF (31.8)
A106: IO1 | B106: =(C106-DATE(YEAR(C106),1,0))/365+YEAR(C106) -> 2026.1397 | C106: 46073 | D106: =ROUND(VLOOKUP(A106,'GB VWR July 1_2025'!A$4:C$33,2,FALSE),1) -> 31.8 | E106: 32.4 | F106: 3.113 | G106: =F106-VLOOKUP(A106,'test well RPs'!A:C,3,FALSE) -> 2.973 | H106: ON
A107: IO1 | B107: =(C107-DATE(YEAR(C107),1,0))/365+YEAR(C107) -> 2026.2329 | C107: 46107 | D107: =ROUND(VLOOKUP(A107,'GB VWR July 1_2025'!A$4:C$33,2,FALSE),1) -> 31.8 | E107: 34.5 | F107: 3 | G107: =F107-VLOOKUP(A107,'test well RPs'!A:C,3,FALSE) -> 2.86 | H107: ON
A108: IO1 | B108: =(C108-DATE(YEAR(C108),1,0))/365+YEAR(C108) -> 2026.3205 | C108: 46139 | D108: =ROUND(VLOOKUP(A108,'GB VWR July 1_2025'!A$4:C$33,2,FALSE),1) -> 31.8 | E108: 34.6 | F108: 3.02 | G108: =F108-VLOOKUP(A108,'test well RPs'!A:C,3,FALSE) -> 2.88 | H108: ON
...

Sheet awc_vwr
A1: Site | B1: Date_Julian | C1: Date | D1: VWR_veg | E1: Adj AWC_soil
A2: BC1 | B2: 1988.67 | C2: =DATE(B2,1,1)+MOD(B2,1)*364 -> 32386.88 | D2: 11.6 | E2: 9.8
A3: BC1 | B3: 1988.76 | C3: =DATE(B3,1,1)+MOD(B3,1)*364 -> 32419.64 | D3: 11.6 | E3: 9.8
A4: BC1 | B4: 1988.86 | C4: =DATE(B4,1,1)+MOD(B4,1)*364 -> 32456.04 | D4: 11.6 | E4: 9.7
A5: BC1 | B5: 1988.94 | C5: =DATE(B5,1,1)+MOD(B5,1)*364 -> 32485.16 | D5: 11.6 | E5: 10.2
A6: BC1 | B6: 1989.16 | C6: =DATE(B6,1,1)+MOD(B6,1)*364 -> 32567.24 | D6: 11.6 | E6: 8.3
A7: BC1 | B7: 1989.24 | C7: =DATE(B7,1,1)+MOD(B7,1)*364 -> 32596.36 | D7: 11.6 | E7: 12.2
A8: BC1 | B8: 1989.33 | C8: =DATE(B8,1,1)+MOD(B8,1)*364 -> 32629.12 | D8: 11.6 | E8: 11.1
A9: BC1 | B9: 1989.41 | C9: =DATE(B9,1,1)+MOD(B9,1)*364 -> 32658.24 | D9: 11.6 | E9: 12.1
A10: BC1 | B10: 1989.49 | C10: =DATE(B10,1,1)+MOD(B10,1)*364 -> 32687.36 | D10: 9.1 | E10: 12.3
A11: BC1 | B11: 1989.58 | C11: =DATE(B11,1,1)+MOD(B11,1)*364 -> 32720.12 | D11: 9.1 | E11: 11.8
A12: BC1 | B12: 1989.66 | C12: =DATE(B12,1,1)+MOD(B12,1)*364 -> 32749.24 | D12: 9.1 | E12: 12.1
A13: BC1 | B13: 1989.75 | C13: =DATE(B13,1,1)+MOD(B13,1)*364 -> 32782 | D13: 9.1 | E13: 12.8
... A294: BC1 | B294: 2023.9068 | C294: =DATE(B294,1,1)+MOD(B294,1)*364 -> 45257.093 | D294: 30.4 | E294: 99.3
A295: BC1 | B295: =(C295-DATE(YEAR(C295),1,0))/365+YEAR(C295) -> 2024.063 | C295: 45314 | D295: 30.4 | E295: 101
A296: BC1 | B296: =(C296-DATE(YEAR(C296),1,0))/365+YEAR(C296) -> 2024.2192 | C296: 45371 | D296: 30.4 | E296: 105.1
A297: BC1 | B297: =(C297-DATE(YEAR(C297),1,0))/365+YEAR(C297) -> 2024.3123 | C297: 45405 | D297: 30.4 | E297: 106.9
A298: BC1 | B298: =(C298-DATE(YEAR(C298),1,0))/365+YEAR(C298) -> 2024.4849 | C298: 45468 | D298: 32.8 | E298: 94
A299: BC1 | B299: =(C299-DATE(YEAR(C299),1,0))/365+YEAR(C299) -> 2024.7205 | C299: 45554 | D299: 32.8 | E299: 81.6
A300: BC1 | B300: =(C300-DATE(YEAR(C300),1,0))/365+YEAR(C300) -> 2024.8877 | C300: 45615 | D300: 32.8 | E300: 80.3
A301: BC1 | B301: =(C301-DATE(YEAR(C301),1,0))/365+YEAR(C301) -> 2025.0767 | C301: 45685 | D301: 32.8 | E301: 81.2
A302: BC1 | B302: =(C302-DATE(YEAR(C302),1,0))/365+YEAR(C302) -> 2025.2329 | C302: 45742 | D302: 32.8 | E302: 86.2
A303: BC1 | B303: =(C303-DATE(YEAR(C303),1,0))/365+YEAR(C303) -> 2025.3041 | C303: 45768 | D303: 32.8 | E303: 85.9
A304: BC1 | B304: =(C304-DATE(YEAR(C304),1,0))/365+YEAR(C304) -> 2025.4849 | C304: 45834 | D304: 22.3 | E304: 76.9
A305: BC1 | B305: =(C305-DATE(YEAR(C305),1,0))/365+YEAR(C305) -> 2025.7315 | C305: 45924 | D305: 22.3 | E305: 67.8
A306: BC1 | B306: =(C306-DATE(YEAR(C306),1,0))/365+YEAR(C306) -> 2025.8849 | C306: 45980 | D306: 22.3 | E306: 72.9
... A309: BC1 | B309: =(C309-DATE(YEAR(C309),1,0))/365+YEAR(C309) -> 2026.3041 | C309: 46133 | D309: 22.3 | E309: 78.5
A310: BC2 | B310: 1989.33 | C310: =DATE(B310,1,1)+MOD(B310,1)*364 -> 32629.12 | D310: 18.3 | E310: 21.3
A311: BC2 | B311: 1989.41 | C311: =DATE(B311,1,1)+MOD(B311,1)*364 -> 32658.24 | D311: 18.3 | E311: 18.8
A312: BC2 | B312: 1989.49 | C312: =DATE(B312,1,1)+MOD(B312,1)*364 -> 32687.36 | D312: 18.3 | E312: 20.4
A313: BC2 | B313: 1989.58 | C313: =DATE(B313,1,1)+MOD(B313,1)*364 -> 32720.12 | D313: 18.3 | E313: 16.2
A314: BC2 | B314: 1989.66 | C314: =DATE(B314,1,1)+MOD(B314,1)*364 -> 32749.24 | D314: 18.3 | E314: 16.7
A315: BC2 | B315: 1989.75 | C315: =DATE(B315,1,1)+MOD(B315,1)*364 -> 32782 | D315: 18.3 | E315: 18.2
A316: BC2 | B316: 1989.83 | C316: =DATE(B316,1,1)+MOD(B316,1)*364 -> 32811.12 | D316: 18.3 | E316: 26.2
A317: BC2 | B317: 1989.91 | C317: =DATE(B317,1,1)+MOD(B317,1)*364 -> 32840.24 | D317: 18.3 | E317: 28.4
A318: BC2 | B318: 1990.16 | C318: =DATE(B318,1,1)+MOD(B318,1)*364 -> 32932.24 | D318: 18.3 | E318: 30.7
A319: BC2 | B319: 1990.24 | C319: =DATE(B319,1,1)+MOD(B319,1)*364 -> 32961.36 | D319: 18.3 | E319: 26.6
A320: BC2 | B320: 1990.33 | C320: =DATE(B320,1,1)+MOD(B320,1)*364 -> 32994.12 | D320: 18.3 | E320: 22.6
A321: BC2 | B321: 1990.41 | C321: =DATE(B321,1,1)+MOD(B321,1)*364 -> 33023.24 | D321: 18.3 | E321: 18.8
... A587: BC2 | B587: 2023.9068 | C587: =DATE(B587,1,1)+MOD(B587,1)*364 -> 45257.093 | D587: 30.4 | E587: 48.3
...

Sheet dtw
A1: Site | B1: Date_Julian | C1: Date | D1: DTW_BGS
A2: BC1 | B2: 1995.57 | C2: =DATE(B2,1,1)+MOD(B2,1)*364 -> 34907.48 | D2: 3.35
A3: BC1 | B3: 1995.66 | C3: =DATE(B3,1,1)+MOD(B3,1)*364 -> 34940.24 | D3: 3.48
A4: BC1 | B4: 1995.74 | C4: =DATE(B4,1,1)+MOD(B4,1)*364 -> 34969.36 | D4: 3.49
A5: BC1 | B5: 1995.83 | C5: =DATE(B5,1,1)+MOD(B5,1)*364 -> 35002.12 | D5: 3.46
A6: BC1 | B6: 1995.91 | C6: =DATE(B6,1,1)+MOD(B6,1)*364 -> 35031.24 | D6: 3.38
A7: BC1 | B7: 1995.99 | C7: =DATE(B7,1,1)+MOD(B7,1)*364 -> 35060.36 | D7: 3.33
A8: BC1 | B8: 1996.08 | C8: =DATE(B8,1,1)+MOD(B8,1)*364 -> 35094.12 | D8: 3.25
A9: BC1 | B9: 1996.16 | C9: =DATE(B9,1,1)+MOD(B9,1)*364 -> 35123.24 | D9: 3.23
A10: BC1 | B10: 1996.24 | C10: =DATE(B10,1,1)+MOD(B10,1)*364 -> 35152.36 | D10: 3.12
A11: BC1 | B11: 1996.33 | C11: =DATE(B11,1,1)+MOD(B11,1)*364 -> 35185.12 | D11: 3.1
A12: BC1 | B12: 1996.41 | C12: =DATE(B12,1,1)+MOD(B12,1)*364 -> 35214.24 | D12: 3.1
A13: BC1 | B13: 1996.49 | C13: =DATE(B13,1,1)+MOD(B13,1)*364 -> 35243.36 | D13: 3.29
... A338: BC1 | B338: 2023.9699 | C338: =DATE(B338,1,1)+MOD(B338,1)*364 -> 45280.03 | D338: 1.347
A339: BC1 | B339: =(C339-DATE(YEAR(C339),1,0))/365+YEAR(C339) -> 2024.063 | C339: 45314 | D339: 1.39
A340: BC1 | B340: =(C340-DATE(YEAR(C340),1,0))/365+YEAR(C340) -> 2024.1452 | C340: 45344 | D340: 1.112
A341: BC1 | B341: =(C341-DATE(YEAR(C341),1,0))/365+YEAR(C341) -> 2024.2192 | C341: 45371 | D341: 1.163
A342: BC1 | B342: =(C342-DATE(YEAR(C342),1,0))/365+YEAR(C342) -> 2024.3123 | C342: 45405 | D342: 0.904
A343: BC1 | B343: =(C343-DATE(YEAR(C343),1,0))/365+YEAR(C343) -> 2024.4082 | C343: 45440 | D343: 1.294
A344: BC1 | B344: =(C344-DATE(YEAR(C344),1,0))/365+YEAR(C344) -> 2024.4849 | C344: 45468 | D344: 1.567
A345: BC1 | B345: =(C345-DATE(YEAR(C345),1,0))/365+YEAR(C345) -> 2024.5616 | C345: 45496 | D345: 1.755
A346: BC1 | B346: =(C346-DATE(YEAR(C346),1,0))/365+YEAR(C346) -> 2024.6575 | C346: 45531 | D346: 1.941
A347: BC1 | B347: =(C347-DATE(YEAR(C347),1,0))/365+YEAR(C347) -> 2024.7205 | C347: 45554 | D347: 2.032
A348: BC1 | B348: =(C348-DATE(YEAR(C348),1,0))/365+YEAR(C348) -> 2024.8137 | C348: 45588 | D348: 2.142
A349: BC1 | B349: =(C349-DATE(YEAR(C349),1,0))/365+YEAR(C349) -> 2024.8877 | C349: 45615 | D349: 2.171
A350: BC1 | B350: =(C350-DATE(YEAR(C350),1,0))/365+YEAR(C350) -> 2024.9699 | C350: 45645 | D350: 2.192
... A367: BC1 | B367: =(C367-DATE(YEAR(C367),1,0))/365+YEAR(C367) -> 2026.4 | C367: 46168 | D367: 2.405
A368: BC2 | B368: 1989.3 | C368: =DATE(B368,1,1)+MOD(B368,1)*364 -> 32618.2 | D368: 4.74
A369: BC2 | B369: 1989.39 | C369: =DATE(B369,1,1)+MOD(B369,1)*364 -> 32650.96 | D369: 4.52
A370: BC2 | B370: 1989.49 | C370: =DATE(B370,1,1)+MOD(B370,1)*364 -> 32687.36 | D370: 4.68
A371: BC2 | B371: 1989.57 | C371: =DATE(B371,1,1)+MOD(B371,1)*364 -> 32716.48 | D371: 4.66
A372: BC2 | B372: 1989.66 | C372: =DATE(B372,1,1)+MOD(B372,1)*364 -> 32749.24 | D372: 4.8
A373: BC2 | B373: 1989.74 | C373: =DATE(B373,1,1)+MOD(B373,1)*364 -> 32778.36 | D373: 4.77
A374: BC2 | B374: 1989.81 | C374: =DATE(B374,1,1)+MOD(B374,1)*364 -> 32803.84 | D374: 4.76
A375: BC2 | B375: 1989.91 | C375: =DATE(B375,1,1)+MOD(B375,1)*364 -> 32840.24 | D375: 4.69
A376: BC2 | B376: 1989.97 | C376: =DATE(B376,1,1)+MOD(B376,1)*364 -> 32862.08 | D376: 4.62
A377: BC2 | B377: 1990.08 | C377: =DATE(B377,1,1)+MOD(B377,1)*364 -> 32903.12 | D377: 4.54
A378: BC2 | B378: 1990.16 | C378: =DATE(B378,1,1)+MOD(B378,1)*364 -> 32932.24 | D378: 4.54
A379: BC2 | B379: 1990.24 | C379: =DATE(B379,1,1)+MOD(B379,1)*364 -> 32961.36 | D379: 4.35
... A782: BC2 | B782: 2023.9699 | C782: =DATE(B782,1,1)+MOD(B782,1)*364 -> 45280.03 | D782: 2.309
...

Sheet on.off
A1: Site | B1: Date_Julian | C1: Date | D1: on.off | E1: on1 | F1: on.off.old | G1: on.off.1
A2: TS1 | B2: 1987.67 | C2: =DATE(B2,1,1)+MOD(B2,1)*364 -> 32021.88 | D2: ON | E2: =IF(D2="ON",1,0) -> 1 | F2: =IF(D2="Off",1,0) -> 0 | G2: =IF(D2="Off",10,1) -> 1
A3: BG2 | B3: 1988.67 | C3: =DATE(B3,1,1)+MOD(B3,1)*364 -> 32386.88 | D3: ON | E3: =IF(D3="ON",1,0) -> 1 | F3: =IF(D3="Off",1,0) -> 0 | G3: =IF(D3="Off",10,1) -> 1
A4: BP2 | B4: 1988.67 | C4: =DATE(B4,1,1)+MOD(B4,1)*364 -> 32386.88 | D4: OFF | E4: =IF(D4="ON",1,0) -> 0 | F4: =IF(D4="Off",1,0) -> 1 | G4: =IF(D4="Off",10,1) -> 10
A5: BP3 | B5: 1988.67 | C5: =DATE(B5,1,1)+MOD(B5,1)*364 -> 32386.88 | D5: ON | E5: =IF(D5="ON",1,0) -> 1 | F5: =IF(D5="Off",1,0) -> 0 | G5: =IF(D5="Off",10,1) -> 1
A6: IO1 | B6: 1988.67 | C6: =DATE(B6,1,1)+MOD(B6,1)*364 -> 32386.88 | D6: ON | E6: =IF(D6="ON",1,0) -> 1 | F6: =IF(D6="Off",1,0) -> 0 | G6: =IF(D6="Off",10,1) -> 1
A7: IO2 | B7: 1988.67 | C7: =DATE(B7,1,1)+MOD(B7,1)*364 -> 32386.88 | D7: ON | E7: =IF(D7="ON",1,0) -> 1 | F7: =IF(D7="Off",1,0) -> 0 | G7: =IF(D7="Off",10,1) -> 1
A8: LW1 | B8: 1988.67 | C8: =DATE(B8,1,1)+MOD(B8,1)*364 -> 32386.88 | D8: ON | E8: =IF(D8="ON",1,0) -> 1 | F8: =IF(D8="Off",1,0) -> 0 | G8: =IF(D8="Off",10,1) -> 1
A9: LW2 | B9: 1988.67 | C9: =DATE(B9,1,1)+MOD(B9,1)*364 -> 32386.88 | D9: ON | E9: =IF(D9="ON",1,0) -> 1 | F9: =IF(D9="Off",1,0) -> 0 | G9: =IF(D9="Off",10,1) -> 1
A10: SS1 | B10: 1988.67 | C10: =DATE(B10,1,1)+MOD(B10,1)*364 -> 32386.88 | D10: ON | E10: =IF(D10="ON",1,0) -> 1 | F10: =IF(D10="Off",1,0) -> 0 | G10: =IF(D10="Off",10,1) -> 1
A11: SS2 | B11: 1988.67 | C11: =DATE(B11,1,1)+MOD(B11,1)*364 -> 32386.88 | D11: ON | E11: =IF(D11="ON",1,0) -> 1 | F11: =IF(D11="Off",1,0) -> 0 | G11: =IF(D11="Off",10,1) -> 1
A12: SS3 | B12: 1988.67 | C12: =DATE(B12,1,1)+MOD(B12,1)*364 -> 32386.88 | D12: ON | E12: =IF(D12="ON",1,0) -> 1 | F12: =IF(D12="Off",1,0) -> 0 | G12: =IF(D12="Off",10,1) -> 1
A13: SS4 | B13: 1988.67 | C13: =DATE(B13,1,1)+MOD(B13,1)*364 -> 32386.88 | D13: ON | E13: =IF(D13="ON",1,0) -> 1 | F13: =IF(D13="Off",1,0) -> 0 | G13: =IF(D13="Off",10,1) -> 1
... A211: SS3 | B211: 2021.23 | C211: =DATE(B211,1,1)+MOD(B211,1)*364 -> 44280.72 | D211: ON | E211: =IF(D211="ON",1,0) -> 1 | F211: =IF(D211="Off",1,0) -> 0 | G211: =IF(D211="Off",10,1) -> 1
A212: TS1 | B212: =(C212-DATE(YEAR(C212),1,0))/365+YEAR(C212) -> 2023.0877 | C212: 44958 | D212: ON | E212: =IF(D212="ON",1,0) -> 1 | F212: =IF(D212="Off",1,0) -> 0 | G212: =IF(D212="Off",10,1) -> 1
A213: IO2 | B213: =(C213-DATE(YEAR(C213),1,0))/365+YEAR(C213) -> 2023.0877 | C213: 44958 | D213: ON | E213: =IF(D213="ON",1,0) -> 1 | F213: =IF(D213="Off",1,0) -> 0 | G213: =IF(D213="Off",10,1) -> 1
A214: TA3 | B214: =(C214-DATE(YEAR(C214),1,0))/365+YEAR(C214) -> 2023.2493 | C214: 45017 | D214: ON | E214: =IF(D214="ON",1,0) -> 1 | F214: =IF(D214="Off",1,0) -> 0 | G214: =IF(D214="Off",10,1) -> 1
A215: SS1 | B215: =(C215-DATE(YEAR(C215),1,0))/365+YEAR(C215) -> 2023.2493 | C215: 45017 | D215: ON | E215: =IF(D215="ON",1,0) -> 1 | F215: =IF(D215="Off",1,0) -> 0 | G215: =IF(D215="Off",10,1) -> 1
A216: SS4 | B216: =(C216-DATE(YEAR(C216),1,0))/365+YEAR(C216) -> 2023.2493 | C216: 45017 | D216: ON | E216: =IF(D216="ON",1,0) -> 1 | F216: =IF(D216="Off",1,0) -> 0 | G216: =IF(D216="Off",10,1) -> 1
A217: IO1 | B217: =(C217-DATE(YEAR(C217),1,0))/365+YEAR(C217) -> 2024.2521 | C217: 45383 | D217: ON | E217: =IF(D217="ON",1,0) -> 1 | F217: =IF(D217="Off",1,0) -> 0 | G217: =IF(D217="Off",10,1) -> 1
A218: IO1 | B218: =(C218-DATE(YEAR(C218),1,0))/365+YEAR(C218) -> 2024.7534 | C218: 45566 | D218: OFF | E218: =IF(D218="ON",1,0) -> 0 | F218: =IF(D218="Off",1,0) -> 1 | G218: =IF(D218="Off",10,1) -> 10
A219: IO1 | B219: =(C219-DATE(YEAR(C219),1,0))/365+YEAR(C219) -> 2025.1644 | C219: 45717 | D219: ON | E219: =IF(D219="ON",1,0) -> 1 | F219: =IF(D219="Off",1,0) -> 0 | G219: =IF(D219="Off",10,1) -> 1
A220: IO1 | B220: =(C220-DATE(YEAR(C220),1,0))/365+YEAR(C220) -> 2025.7507 | C220: 45931 | D220: OFF | E220: =IF(D220="ON",1,0) -> 0 | F220: =IF(D220="Off",1,0) -> 1 | G220: =IF(D220="Off",10,1) -> 10
A221: IO1 | B221: =(C221-DATE(YEAR(C221),1,0))/365+YEAR(C221) -> 2026.1644 | C221: 46082 | D221: ON | E221: =IF(D221="ON",1,0) -> 1 | F221: =IF(D221="Off",1,0) -> 0 | G221: =IF(D221="Off",10,1) -> 1
A222: BP2 | B222: =(C222-DATE(YEAR(C222),1,0))/365+YEAR(C222) -> 2026.4164 | C222: 46174 | D222: OFF | E222: =IF(D222="ON",1,0) -> 0 | F222: =IF(D222="Off",1,0) -> 1 | G222: =IF(D222="Off",10,1) -> 10
A223: SS2 | B223: =(C223-DATE(YEAR(C223),1,0))/365+YEAR(C223) -> 2026.4164 | C223: 46174 | D223: OFF | E223: =IF(D223="ON",1,0) -> 0 | F223: =IF(D223="Off",1,0) -> 1 | G223: =IF(D223="Off",10,1) -> 10

Sheet on.off.table
A1: site | B1: 45931 | C1: current.status | D1: AWC.req.turnon
A3: LW1 | B3: ON | C3: ON | D3: NA
A4: LW2 | B4: ON | C4: ON | D4: NA
A5: LW3 | B5: ON | C5: ON | D5: NA
A6: BP1 | B6: ON | C6: ON | D6: NA
A7: BP2 | B7: OFF | C7: OFF | D7: 28.4, OFF 7-98
A8: BP3 | B8: ON | C8: ON | D8: NA
A9: BP4 | B9: ON | C9: ON | D9: NA
A10: TA3 | B10: ON | C10: ON | D10: NA
A11: TA4 | B11: ON | C11: ON | D11: NA
A12: TA5 | B12: ON | C12: ON | D12: NA
A13: TA6 | B13: ON | C13: ON | D13: NA
A14: TS1 | B14: ON | C14: ON | D14: NA
... A24: BG2 | B24: ON | C24: ON | D24: NA

Sheet test well RPs
A1: Site | B1: MW STAID | C1: RP_m | D1: Notes
A2: LW1 | B2: T795 | C2: 0.18
A3: LW2 | B3: V001G | C3: 0.67 | D3: steel RP; inner PVC RP offset = 0.104m
A4: LW3 | B4: T840 | C4: 0.53
A5: BC1 | B5: T02AI | C5: 0.07
A6: BC2 | B6: T796 | C6: 0.2
A7: BC3 | B7: T797 | C7: 0.07
A8: BP1 | B8: T798 | C8: 0.12
A9: BP2 | B9: T799 | C9: 0.21
A10: BP3 | B10: T567 | C10: 0.16
A11: BP4 | B11: T800 | C11: 0.16
A12: TA1 | B12: T419 | C12: 0.47
A13: TA3 | B13: T849 | C13: 0.493
A14: TA4 | B14: T586 | C14: 0.07
A15: TA5 | B15: T801 | C15: 0.07 | D15: RP=0.190 before 5/1995
A16: TA6 | B16: T803 | C16: 0.13
A17: TAC | B17: T802 | C17: 0.2 | D17: RP=0.06 before 5/2002; RP=1.60 before 4/1995; RP=0.23 before 11/1993
A18: TS1 | B18: T807 | C18: 0.16
A19: TS2 | B19: T806 | C19: 0.14 | D19: PVC RP
A20: TS3 | B20: T851 | C20: 0.59
A21: TS4 | B21: T804 | C21: 0.16
A22: TS6 | B22: T808 | C22: 0.12 | D22: RP=0.420 before 7/1998
A23: TSC | B23: T805 | C23: 0.16
A24: IO1 | B24: T809 | C24: 0.14
A25: IO2 | B25: T854 | C25: 0.583
A26: IC1 | B26: T008D | C26: 0.2
A27: IC2 | B27: T810 | C27: 0.16
A28: SS1 | B28: V009G | C28: 0.91
A29: SS2 | B29: T646 | C29: 0.43
A30: SS3 | B30: T884 | C30: 0.683 | D30: T561 before 10/2008 (RP=0.510)
A31: SS4 | B31: T885 | C31: 0.701 | D31: T811 before 10/2008 (RP=0.170)
A32: BG2 | B32: T812 | C32: 0.35 | D32: RP=0.180 before 4/2002
A33: BGC | B33: T856 | C33: 0.49 | D33: steel RP

Sheet GB VWR July 1_2025
B1: VWR (cm): 2025
A2: SITE | B2: Oct 1 | C2: July 1
B3: cm | C3: cm
A4: LW1 | B4: 11.282635 | C4: 6.4048503
A5: LW2 | B5: 3.4946108 | C5: 1.9266467
A6: LW3 | B6: 9.6952096 | C6: 5.2756287
A7: BC1 | B7: 22.2524 | C7: 12.123966
A8: BC2 | B8: 19.096269 | C8: 10.181059
A9: BC3 | B9: 18.014834 | C9: 9.687035
A10: BP1 | B10: 14.802216 | C10: 8.0594048
A11: BP2 | B11: 15.013275 | C11: 8.1119244
A12: BP3 | B12: 8.8724551 | C12: 4.9934132
A13: BP4 | B13: 5.589128 | C13: 3.1624794
A14: TA3 | B14: 14.533975 | C14: 7.7556179
A15: TA4 | B15: 9.1669461 | C15: 4.9156647
... A33: BGC | B33: 8.4011976 | C33: 4.5345509
